Workbook
Name Slicer_Country: #N/A
Name Slicer_Month: #N/A
Name Slicer_NewChannel: #N/A
Name Slicer_NewSalesperson: #N/A
Name Slicer_ProductCategory: #N/A
Name Slicer_Region: #N/A

Sheet CohotAnalysis
A3: Row Labels | B3: Sum of GrossRevenue
A4: 01-2023 | B4: 10090676
A5: Brazil | B5: 1037852
A6: Canada | B6: 882622.98
A7: China | B7: 899054.11
A8: France | B8: 758280.92
A9: Germany | B9: 929424.89
A10: India | B10: 1092333.4
A11: Kenya | B11: 947364.87
A12: Nigeria | B12: 881838.68
A13: South Africa | B13: 779927.34
A14: United Kingdom | B14: 1113282.1
A15: USA | B15: 768694.59
... A18: Grand Total | B18: 10945749

Sheet SKUAnalysis
A3: Sum of GrossRevenue | B3: Column Labels
A4: Row Labels | B4: A | C4: B | D4: C | E4: Grand Total
A5: ACC-1021 | D5: 1446.9507 | E5: 1446.9507
A6: ACC-1028 | C6: 10693.885 | E6: 10693.885
A7: ACC-1060 | D7: 5610.0924 | E7: 5610.0924
A8: ACC-1075 | C8: 10893.623 | E8: 10893.623
A9: ACC-1238 | B9: 27465.648 | E9: 27465.648
A10: ACC-1249 | B10: 14431.738 | E10: 14431.738
A11: ACC-1375 | B11: 31513.085 | E11: 31513.085
A12: ACC-1492 | C12: 7382.145 | E12: 7382.145
A13: ACC-1596 | C13: 7507.4515 | E13: 7507.4515
A14: ACC-1604 | C14: 12040.644 | E14: 12040.644
A15: ACC-1659 | B15: 28386.016 | E15: 28386.016
A16: ACC-1663 | C16: 7578.84 | E16: 7578.84
A17: ACC-1731 | B17: 22620.86 | E17: 22620.86
A18: ACC-1770 | D18: 272.986 | E18: 272.986
A19: ACC-1882 | B19: 17964.404 | E19: 17964.404
A20: ACC-2252 | D20: 4569.8508 | E20: 4569.8508
A21: ACC-2364 | C21: 9829.0483 | E21: 9829.0483
A22: ACC-2386 | D22: 5960.334 | E22: 5960.334
A23: ACC-2735 | B23: 14549.029 | E23: 14549.029
A24: ACC-2761 | C24: 10647.727 | E24: 10647.727
A25: ACC-2867 | C25: 8644.6696 | E25: 8644.6696
A26: ACC-2902 | C26: 7969.4615 | E26: 7969.4615
A27: ACC-2903 | C27: 11283.401 | E27: 11283.401
A28: ACC-2988 | B28: 53034.364 | E28: 53034.364
A29: ACC-2990 | D29: 1547.35 | E29: 1547.35
A30: ACC-3068 | C30: 7105.3528 | E30: 7105.3528
A31: ACC-3103 | B31: 23195.018 | E31: 23195.018
A32: ACC-3349 | D32: 1010.3759 | E32: 1010.3759
A33: ACC-3385 | C33: 10388.43 | E33: 10388.43
A34: ACC-3415 | B34: 15530.93 | E34: 15530.93
A35: ACC-3551 | D35: 908.037 | E35: 908.037
A36: ACC-3567 | C36: 7568.9632 | E36: 7568.9632
A37: ACC-3645 | B37: 19628.477 | E37: 19628.477
A38: ACC-3721 | B38: 22526.66 | E38: 22526.66
A39: ACC-3833 | C39: 6732.4334 | E39: 6732.4334
A40: ACC-3951 | C40: 7235.2135 | E40: 7235.2135
A41: ACC-3961 | C41: 10936.992 | E41: 10936.992
A42: ACC-3989 | C42: 10382.659 | E42: 10382.659
...

Sheet Cannibalization
A3: Sum of GrossRevenue | B3: Column Labels
A4: Row Labels | B4: Direct | C4: Distributor | D4: Marketplace | E4: Online | F4: Retail | G4: Grand Total
A5: Africa | B5: 0.042229772 | C5: 0.060964173 | D5: 0.048189289 | E5: 0.039595858 | F5: 0.047390235 | G5: 0.23836933
A6: Americas | B6: 0.069536141 | C6: 0.051971172 | D6: 0.033471983 | E6: 0.063033735 | F6: 0.027668602 | G6: 0.24568163
A7: Asia | B7: 0.058721723 | C7: 0.046540332 | D7: 0.053672492 | E7: 0.037791978 | F7: 0.063325193 | G7: 0.26005172
A8: Europe | B8: 0.076980975 | C8: 0.029561121 | D8: 0.052045458 | E8: 0.053482563 | F8: 0.043827206 | G8: 0.25589732
A9: Grand Total | B9: 0.24746861 | C9: 0.1890368 | D9: 0.18737922 | E9: 0.19390413 | F9: 0.18221124 | G9: 1

Sheet Top3RevperOrder
A3: Row Labels | B3: Sum of GrossRevenue | C3: Sum of GrossProfit
A4: B. Chen | B4: 893735.66 | C4: 359716.93
A5: K. Singh | B5: 883348.13 | C5: 297798.44
A6: M. Rossi | B6: 976696.7 | C6: 363428.29
A7: Grand Total | B7: 2753780.5 | C7: 1020943.7

Sheet Bottom3RevperOrder
A3: Row Labels | B3: Sum of GrossRevenue | C3: Sum of GrossProfit
A4: A. Patel | B4: 979572.27 | C4: 375845.12
A5: B. Chen | B5: 933252.47 | C5: 380805.21
A6: C. Otieno | B6: 689776.36 | C6: 237357.22
A7: D. Smith | B7: 576820.19 | C7: 203186.69
A8: E. Garcia | B8: 543846.44 | C8: 219222.23
A9: F. Müller | B9: 812637.17 | C9: 292994.34
A10: G. Dubois | B10: 510653.71 | C10: 173517.26
A11: H. Kim | B11: 749851.6 | C11: 336984.24
A12: I. Johnson | B12: 541165.67 | C12: 198714.78
A13: J. Njeri | B13: 802384.66 | C13: 333460.55
A14: K. Singh | B14: 913477.32 | C14: 305380.91
A15: L. Okafor | B15: 853458.04 | C15: 289448.3
... A19: Grand Total | B19: 10945749 | C19: 4058529.3

Sheet RevenueByMonth
A3: Row Labels | B3: Sum of GrossRevenue
A4: Jan | B4: 701241.31
A5: Feb | B5: 963301
A6: Mar | B6: 799192.62
A7: Apr | B7: 947246.58
A8: May | B8: 1262901.9
A9: Jun | B9: 1252974.2
A10: Jul | B10: 1323460
A11: Aug | B11: 1090009.6
A12: Sep | B12: 661140.77
A13: Oct | B13: 663847.32
A14: Nov | B14: 543953.69
A15: Dec | B15: 736480.3
A16: Grand Total | B16: 10945749

Sheet ProfitByReg&Chanel
A3: Sum of GrossProfit | B3: Column Labels
A4: Row Labels | B4: Africa | C4: Americas | D4: Asia | E4: Europe | F4: Grand Total
A5: Direct | B5: 187203.7 | C5: 260636.72 | D5: 256155.81 | E5: 301850.55 | F5: 1005846.8
A6: Distributor | B6: 232409.49 | C6: 230034.23 | D6: 172459.12 | E6: 119311.2 | F6: 754214.03
A7: Marketplace | B7: 186864.8 | C7: 115566.17 | D7: 199689.53 | E7: 270217.14 | F7: 772337.64
A8: Online | B8: 180839.19 | C8: 265252.12 | D8: 152920.54 | E8: 219741.99 | F8: 818753.84
A9: Retail | B9: 190525.56 | C9: 87507.989 | D9: 223965.87 | E9: 205377.6 | F9: 707377.02
A10: Grand Total | B10: 977842.74 | C10: 958997.23 | D10: 1005190.9 | E10: 1116498.5 | F10: 4058529.3

Sheet Top10SKUbyRev
A3: Row Labels | B3: Sum of GrossRevenue
A4: NET-5987 | B4: 82141.34
A5: NET-5523 | B5: 79548.756
A6: NET-2365 | B6: 109244
A7: MON-6962 | B7: 92715.25
A8: MON-6699 | B8: 85637.74
A9: MON-2266 | B9: 87404.93
A10: LAP-8910 | B10: 102122.94
A11: LAP-3904 | B11: 82514.712
A12: CMP-8851 | B12: 139277.83
A13: CMP-3938 | B13: 84136.12
A14: Grand Total | B14: 944743.62

Sheet LeadTimeDays
A3: Average of MetTarget | B3: Column Labels
A4: Row Labels | B4: Brazil | C4: Canada | D4: China | E4: France | F4: Germany | G4: India | H4: Japan | I4: Kenya | J4: Nigeria | K4: South Africa | L4: United Kingdom | M4: USA | N4: Grand Total
A5: Accessories | B5: 0.4 | C5: 0.33333333 | D5: 0.75 | E5: 0.14285714 | F5: 0.44444444 | G5: 0.25 | H5: 0.2 | I5: 0.4 | J5: 0.46153846 | K5: 0.5 | L5: 0.125 | M5: 0.5 | N5: 0.36363636
A6: Components | B6: 0.14285714 | C6: 0.5 | D6: 0 | E6: 0.3 | F6: 0.33333333 | G6: 0.2 | H6: 0.375 | I6: 0.2 | J6: 0.33333333 | K6: 0.45454545 | L6: 0.28571429 | M6: 0.4 | N6: 0.28571429
A7: Laptops | B7: 0.2 | C7: 0.33333333 | D7: 0.2 | E7: 0.33333333 | F7: 0.28571429 | G7: 0.11111111 | H7: 0.42857143 | I7: 0.7 | J7: 0.5 | K7: 0.28571429 | L7: 0.44444444 | M7: 0.2 | N7: 0.35365854
A8: Monitors | B8: 0.25 | C8: 0 | D8: 0.16666667 | E8: 0.3 | F8: 0.1 | G8: 0.16666667 | H8: 0.28571429 | I8: 0 | J8: 0.6 | K8: 0.14285714 | L8: 0.28571429 | M8: 0.11111111 | N8: 0.20212766
A9: Networking | B9: 0.16666667 | C9: 0 | D9: 0.5 | E9: 0.33333333 | F9: 0.25 | G9: 0.14285714 | H9: 0.083333333 | I9: 0.33333333 | J9: 0.5 | K9: 0.28571429 | L9: 0.22222222 | M9: 0.5 | N9: 0.26744186
A10: Phones | B10: 0.55555556 | C10: 0 | D10: 0.14285714 | E10: 0 | F10: 0.14285714 | G10: 0.22222222 | H10: 0.090909091 | I10: 0.13333333 | J10: 0.16666667 | K10: 0.5 | L10: 0.25 | M10: 0.1 | N10: 0.19318182
A11: Printers | B11: 0.28571429 | C11: 0.15384615 | D11: 0 | E11: 0.16666667 | F11: 0.125 | G11: 0.33333333 | H11: 0.33333333 | I11: 0.125 | J11: 0.5 | K11: 0.2 | L11: 0.3 | M11: 0.75 | N11: 0.25242718
A12: Grand Total | B12: 0.29032258 | C12: 0.20454545 | D12: 0.19607843 | E12: 0.24074074 | F12: 0.23529412 | G12: 0.19672131 | H12: 0.23728814 | I12: 0.30357143 | J12: 0.43181818 | K12: 0.33333333 | L12: 0.27777778 | M12: 0.35294118 | N12: 0.2721519

Sheet OutliersbySalespersonandRegion
B3: Column Labels
B4: Africa | D4: Americas | F4: Asia | H4: Europe | J4: Total Average of HighestDscnt | K4: Total Count of OrderID
A5: Row Labels | B5: Average of HighestDscnt | C5: Count of OrderID | D5: Average of HighestDscnt | E5: Count of OrderID | F5: Average of HighestDscnt | G5: Count of OrderID | H5: Average of HighestDscnt | I5: Count of OrderID
A6: A. Patel | B6: 0.17647059 | C6: 17 | D6: 0.5 | E6: 10 | F6: 0 | G6: 10 | H6: 0.1 | I6: 10 | J6: 0.19148936 | K6: 47
A7: B. Chen | B7: 0 | C7: 8 | D7: 0.125 | E7: 8 | F7: 0.11764706 | G7: 17 | H7: 0.125 | I7: 16 | J7: 0.10204082 | K7: 49
A8: C. Otieno | B8: 0.25 | C8: 8 | D8: 0.14285714 | E8: 14 | F8: 0.3 | G8: 10 | H8: 0.2 | I8: 5 | J8: 0.21621622 | K8: 37
A9: D. Smith | B9: 0.2 | C9: 10 | D9: 0.5 | E9: 8 | F9: 0.11111111 | G9: 9 | H9: 0.090909091 | I9: 11 | J9: 0.21052632 | K9: 38
A10: E. Garcia | B10: 0.2 | C10: 5 | D10: 0 | E10: 5 | F10: 0 | G10: 8 | H10: 0.125 | I10: 16 | J10: 0.088235294 | K10: 34
A11: F. Müller | B11: 0 | C11: 13 | D11: 0.066666667 | E11: 15 | F11: 0.25 | G11: 12 | H11: 0 | I11: 11 | J11: 0.078431373 | K11: 51
A12: G. Dubois | B12: 0 | C12: 3 | D12: 0.125 | E12: 8 | F12: 0.090909091 | G12: 11 | H12: 0.125 | I12: 8 | J12: 0.1 | K12: 30
A13: H. Kim | B13: 0.14285714 | C13: 7 | D13: 0.083333333 | E13: 12 | F13: 0.125 | G13: 16 | H13: 0.076923077 | I13: 13 | J13: 0.10416667 | K13: 48
A14: I. Johnson | B14: 0.25 | C14: 8 | D14: 0.35714286 | E14: 14 | F14: 0.125 | G14: 8 | H14: 0.125 | I14: 8 | J14: 0.23684211 | K14: 38
A15: J. Njeri | B15: 0.25 | C15: 12 | D15: 0 | E15: 10 | F15: 0.10526316 | G15: 19 | H15: 0.11111111 | I15: 9 | J15: 0.12 | K15: 50
A16: K. Singh | B16: 0 | C16: 14 | D16: 0.1 | E16: 10 | F16: 0.11111111 | G16: 9 | H16: 0.15384615 | I16: 13 | J16: 0.086956522 | K16: 46
A17: L. Okafor | B17: 0.2 | C17: 10 | D17: 0.25 | E17: 12 | F17: 0.21428571 | G17: 14 | H17: 0 | I17: 10 | J17: 0.17391304 | K17: 46
... A21: Grand Total | B21: 0.15172414 | C21: 145 | D21: 0.17197452 | E21: 157 | F21: 0.14035088 | G21: 171 | H21: 0.10691824 | I21: 159 | J21: 0.14240506 | K21: 632

Sheet Revenue by productcategory
A3: Row Labels | B3: Sum of GrossRevenue
A4: Accessories | B4: 1342046.6
A5: Components | B5: 1550200.5
A6: Laptops | B6: 1711094.4
A7: Monitors | B7: 1551590.9
A8: Networking | B8: 1774683.1
A9: Phones | B9: 1399242.2
A10: Printers | B10: 1616910.2
A11: Grand Total | B11: 10945768

Sheet Data
A1: OrderID | B1: OrderDate | C1: NewOrderDate | D1: RequiredDate | E1: NewRequiredDate | F1: LeadTimedays | G1: MetTarget | H1: Month | I1: Quarters | J1: FirstOrderDate | K1: FirstOrderMonth | L1: Region | M1: Country | N1: City | O1: NewCity | P1: CustomerSegment | Q1: Channel | R1: NewChannel | S1: Salesperson | T1: NewSalesperson | U1: ProductCategory | V1: PriceBand | W1: SKU | X1: SKUcategory | Y1: UnitCost | Z1: UnitPrice | AA1: NewUnitPrice | AB1: DiscountPct | AC1: NewDiscountPct | AD1: HighestDscnt | AE1: Quantity | AF1: GrossRevenue | AG1: CostOfGoods | AH1: GrossProfit | AI1: MarginPct | AJ1: C.Rev | AK1: C.Pct | AL1: ScenarioDiscount | AM1: ScenarioQuantity | AN1: ScenarioUnitCost | AO1: ScenarioRevenue
A2: ORD-2025-132174 | B2: 45855 | C2: =IF(D2<B2,D2,B2) -> 45855 | D2: 45861 | E2: =IF(D2<B2,B2,D2) -> 45861 | F2: =E2-C2 -> 6 | G2: =IF(Data!F2<=7,1,0) -> 1 | H2: =TEXT(C2,"MM-YYYY") -> 07-2025 | I2: ="Q"&ROUNDUP(MONTH(H2)/3,0)&"-"&YEAR(H2) -> Q3-2025 | J2: =_xlfn.MINIFS(C:C,M:M,M2) -> 44928 | K2: =TEXT(J2,"MM-YYYY") -> 01-2023 | L2: Americas | M2: Canada | N2: Vancouver | O2: =IF(N2="",_xlfn.XLOOKUP(M2,M:M,N:N),N2) -> Vancouver | P2: Consumer | Q2: Online | R2: =IF(Q2="",_xlfn.XLOOKUP(M2,M:M,Q:Q),Q2) -> Online | S2: H. Kim | T2: =IF(S2="",_xlfn.XLOOKUP(L2,L:L,S:S),S2) -> H. Kim | U2: Components | V2: =IF(AA2<815.0987,"Low",IF(AA2<1640.058,"Medium","High")) -> High | W2: CMP-8851 | X2: =IF(AK2<=80%,"A",IF(AK2<=95%,"B","C")) -> A | Y2: 1364.89 | Z2: 2757.54 | AA2: =ABS(Z2) -> 2757.54 | AB2: 0.172 | AC2: =MIN(AB2,30%) -> 0.172 | AD2: =IF(AC2>20%,1,0) -> 0 | AE2: 61 | AF2: =AA2*AE2*(1-AC2) -> 139277.83 | AG2: =Y2*AE2 -> 83258.29 | AH2: =ABS(AF2-AG2) -> 56019.54 | AI2: =IF(AF2=0,0,AH2/AF2) -> 0.40221434 | AJ2: 139277.83 | AK2: =AJ2/SUM(AF:AF) -> 0.012724354 | AL2: =MIN(AC2,'What-If Analysis'!$B$2) -> 0.172 | AM2: =AE2*(1+'What-If Analysis'!$B$3) -> 79.3 | AN2: =Y2*(1+'What-If Analysis'!$B$4) -> 1501.379 | AO2: =AA2*AM2*(1-AL2) -> 181061.18
A3: ORD-2025-639542 | B3: 45817 | C3: =IF(D3<B3,D3,B3) -> 45817 | D3: 45826 | E3: =IF(D3<B3,B3,D3) -> 45826 | F3: =E3-C3 -> 9 | G3: =IF(Data!F624<=7,1,0) -> 1 | H3: =TEXT(C3,"MM-YYYY") -> 06-2025 | I3: ="Q"&ROUNDUP(MONTH(H3)/3,0)&"-"&YEAR(H3) -> Q2-2025 | J3: =_xlfn.MINIFS(C:C,M:M,M3) -> 44936 | K3: =TEXT(J3,"MM-YYYY") -> 01-2023 | L3: Europe | M3: France | N3: Marseille | O3: =IF(N3="",_xlfn.XLOOKUP(M3,M:M,N:N),N3) -> Marseille | P3: Small Business | Q3: Marketplace | R3: =IF(Q3="",_xlfn.XLOOKUP(M3,M:M,Q:Q),Q3) -> Marketplace | S3: H. Kim | T3: =IF(S3="",_xlfn.XLOOKUP(L3,L:L,S:S),S3) -> H. Kim | U3: Accessories | V3: =IF(AA3<815.0987,"Low",IF(AA3<1640.058,"Medium","High")) -> Low | W3: ACC-1770 | X3: =IF(AK3<=80%,"A",IF(AK3<=95%,"B","C")) -> A | Y3: 1225.5 | Z3: -5.27 | AA3: =ABS(Z3) -> 5.27 | AB3: 0.075 | AC3: =MIN(AB3,30%) -> 0.075 | AD3: =IF(AC3>20%,1,0) -> 0 | AE3: 56 | AF3: =AA3*AE3*(1-AC3) -> 272.986 | AG3: =Y3*AE3 -> 68628 | AH3: =ABS(AF3-AG3) -> 68355.014 | AI3: =IF(AF3=0,0,AH3/AF3) -> 250.39751 | AJ3: =AJ2+AF3 -> 139550.82 | AK3: =AJ3/SUM(AF:AF) -> 0.012749294 | AL3: =MIN(AC3,'What-If Analysis'!$B$2) -> 0.075 | AM3: =AE3*(1+'What-If Analysis'!$B$3) -> 72.8 | AN3: =Y3*(1+'What-If Analysis'!$B$4) -> 1348.05 | AO3: =AA3*AM3*(1-AL3) -> 354.8818
A4: ORD-2023-906481 | B4: 45048 | C4: =IF(D4<B4,D4,B4) -> 45048 | D4: 45064 | E4: =IF(D4<B4,B4,D4) -> 45064 | F4: =E4-C4 -> 16 | G4: =IF(Data!F6<=7,1,0) -> 1 | H4: =TEXT(C4,"MM-YYYY") -> 05-2023 | I4: ="Q"&ROUNDUP(MONTH(H4)/3,0)&"-"&YEAR(H4) -> Q2-2023 | J4: =_xlfn.MINIFS(C:C,M:M,M4) -> 44955 | K4: =TEXT(J4,"MM-YYYY") -> 01-2023 | L4: Asia | M4: India | N4: Delhi | O4: =IF(N4="",_xlfn.XLOOKUP(M4,M:M,N:N),N4) -> Delhi | P4: Small Business | Q4: Marketplace | R4: =IF(Q4="",_xlfn.XLOOKUP(M4,M:M,Q:Q),Q4) -> Marketplace | S4: K. Singh | T4: =IF(S4="",_xlfn.XLOOKUP(L4,L:L,S:S),S4) -> K. Singh | U4: Monitors | V4: =IF(AA4<815.0987,"Low",IF(AA4<1640.058,"Medium","High")) -> High | W4: MON-2266 | X4: =IF(AK4<=80%,"A",IF(AK4<=95%,"B","C")) -> A | Y4: 1463.92 | Z4: 2252.24 | AA4: =ABS(Z4) -> 2252.24 | AB4: 0.118 | AC4: =MIN(AB4,30%) -> 0.118 | AD4: =IF(AC4>20%,1,0) -> 0 | AE4: 44 | AF4: =AA4*AE4*(1-AC4) -> 87404.93 | AG4: =Y4*AE4 -> 64412.48 | AH4: =ABS(AF4-AG4) -> 22992.45 | AI4: =IF(AF4=0,0,AH4/AF4) -> 0.26305667 | AJ4: =AJ3+AF4 -> 226955.75 | AK4: =AJ4/SUM(AF:AF) -> 0.020734566 | AL4: =MIN(AC4,'What-If Analysis'!$B$2) -> 0.118 | AM4: =AE4*(1+'What-If Analysis'!$B$3) -> 57.2 | AN4: =Y4*(1+'What-If Analysis'!$B$4) -> 1610.312 | AO4: =AA4*AM4*(1-AL4) -> 113626.41
A5: ORD-2024-247979 | B5: 45598 | C5: =IF(D5<B5,D5,B5) -> 45598 | D5: 45614 | E5: =IF(D5<B5,B5,D5) -> 45614 | F5: =E5-C5 -> 16 | G5: =IF(Data!F13<=7,1,0) -> 0 | H5: =TEXT(C5,"MM-YYYY") -> 11-2024 | I5: ="Q"&ROUNDUP(MONTH(H5)/3,0)&"-"&YEAR(H5) -> Q4-2024 | J5: =_xlfn.MINIFS(C:C,M:M,M5) -> 44955 | K5: =TEXT(J5,"MM-YYYY") -> 01-2023 | L5: Asia | M5: India | N5: Mumbai | O5: =IF(N5="",_xlfn.XLOOKUP(M5,M:M,N:N),N5) -> Mumbai | P5: Small Business | Q5: Distributor | R5: =IF(Q5="",_xlfn.XLOOKUP(M5,M:M,Q:Q),Q5) -> Distributor | S5: O. Wang | T5: =IF(S5="",_xlfn.XLOOKUP(L5,L:L,S:S),S5) -> O. Wang | U5: Monitors | V5: =IF(AA5<815.0987,"Low",IF(AA5<1640.058,"Medium","High")) -> High | W5: MON-5188 | X5: =IF(AK5<=80%,"A",IF(AK5<=95%,"B","C")) -> A | Y5: 1233.58 | Z5: 1912.51 | AA5: =ABS(Z5) -> 1912.51 | AB5: 0.255 | AC5: =MIN(AB5,30%) -> 0.255 | AD5: =IF(AC5>20%,1,0) -> 1 | AE5: 51 | AF5: =AA5*AE5*(1-AC5) -> 72665.817 | AG5: =Y5*AE5 -> 62912.58 | AH5: =ABS(AF5-AG5) -> 9753.2375 | AI5: =IF(AF5=0,0,AH5/AF5) -> 0.13422043 | AJ5: =AJ4+AF5 -> 299621.56 | AK5: =AJ5/SUM(AF:AF) -> 0.027373279 | AL5: =MIN(AC5,'What-If Analysis'!$B$2) -> 0.2 | AM5: =AE5*(1+'What-If Analysis'!$B$3) -> 66.3 | AN5: =Y5*(1+'What-If Analysis'!$B$4) -> 1356.938 | AO5: =AA5*AM5*(1-AL5) -> 101439.53
A6: ORD-2025-650841 | B6: 45841 | C6: =IF(D6<B6,D6,B6) -> 45841 | D6: 45844 | E6: =IF(D6<B6,B6,D6) -> 45844 | F6: =E6-C6 -> 3 | G6: =IF(Data!F4<=7,1,0) -> 0 | H6: =TEXT(C6,"MM-YYYY") -> 07-2025 | I6: ="Q"&ROUNDUP(MONTH(H6)/3,0)&"-"&YEAR(H6) -> Q3-2025 | J6: =_xlfn.MINIFS(C:C,M:M,M6) -> 44939 | K6: =TEXT(J6,"MM-YYYY") -> 01-2023 | L6: Africa | M6: Nigeria | N6: Lagos | O6: =IF(N6="",_xlfn.XLOOKUP(M6,M:M,N:N),N6) -> Lagos | P6: Consumer | Q6: Online | R6: =IF(Q6="",_xlfn.XLOOKUP(M6,M:M,Q:Q),Q6) -> Online | T6: A. Patel | U6: Laptops | V6: =IF(AA6<815.0987,"Low",IF(AA6<1640.058,"Medium","High")) -> High | W6: LAP-8910 | X6: =IF(AK6<=80%,"A",IF(AK6<=95%,"B","C")) -> A | Y6: 1313.3 | Z6: 2884.34 | AA6: =ABS(Z6) -> 2884.34 | AB6: 0.157 | AC6: =MIN(AB6,30%) -> 0.157 | AD6: =IF(AC6>20%,1,0) -> 0 | AE6: 42 | AF6: =AA6*AE6*(1-AC6) -> 102122.94 | AG6: =Y6*AE6 -> 55158.6 | AH6: =ABS(AF6-AG6) -> 46964.342 | AI6: =IF(AF6=0,0,AH6/AF6) -> 0.45988043 | AJ6: =AJ5+AF6 -> 401744.51 | AK6: =AJ6/SUM(AF:AF) -> 0.036703181 | AL6: =MIN(AC6,'What-If Analysis'!$B$2) -> 0.157 | AM6: =AE6*(1+'What-If Analysis'!$B$3) -> 54.6 | AN6: =Y6*(1+'What-If Analysis'!$B$4) -> 1444.63 | AO6: =AA6*AM6*(1-AL6) -> 132759.82
A7: ORD-2023-884625 | B7: 44976 | C7: =IF(D7<B7,D7,B7) -> 44976 | D7: 44997 | E7: =IF(D7<B7,B7,D7) -> 44997 | F7: =E7-C7 -> 21 | G7: =IF(Data!F7<=7,1,0) -> 0 | H7: =TEXT(C7,"MM-YYYY") -> 02-2023 | I7: ="Q"&ROUNDUP(MONTH(H7)/3,0)&"-"&YEAR(H7) -> Q1-2023 | J7: =_xlfn.MINIFS(C:C,M:M,M7) -> 44947 | K7: =TEXT(J7,"MM-YYYY") -> 01-2023 | L7: Europe | M7: Germany | N7: Berlin | O7: =IF(N7="",_xlfn.XLOOKUP(M7,M:M,N:N),N7) -> Berlin | P7: Small Business | Q7: Direct | R7: =IF(Q7="",_xlfn.XLOOKUP(M7,M:M,Q:Q),Q7) -> Direct | S7: L. Okafor | T7: =IF(S7="",_xlfn.XLOOKUP(L7,L:L,S:S),S7) -> L. Okafor | U7: Monitors | V7: =IF(AA7<815.0987,"Low",IF(AA7<1640.058,"Medium","High")) -> High | W7: MON-6699 | X7: =IF(AK7<=80%,"A",IF(AK7<=95%,"B","C")) -> A | Y7: 1234.81 | Z7: 2055.24 | AA7: =ABS(Z7) -> 2055.24 | AB7: 0.053 | AC7: =MIN(AB7,30%) -> 0.053 | AD7: =IF(AC7>20%,1,0) -> 0 | AE7: 44 | AF7: =AA7*AE7*(1-AC7) -> 85637.74 | AG7: =Y7*AE7 -> 54331.64 | AH7: =ABS(AF7-AG7) -> 31306.1 | AI7: =IF(AF7=0,0,AH7/AF7) -> 0.3655643 | AJ7: =AJ6+AF7 -> 487382.25 | AK7: =AJ7/SUM(AF:AF) -> 0.044527003 | AL7: =MIN(AC7,'What-If Analysis'!$B$2) -> 0.053 | AM7: =AE7*(1+'What-If Analysis'!$B$3) -> 57.2 | AN7: =Y7*(1+'What-If Analysis'!$B$4) -> 1358.291 | AO7: =AA7*AM7*(1-AL7) -> 111329.06
A8: ORD-2025-845715 | B8: 45761 | C8: =IF(D8<B8,D8,B8) -> 45761 | D8: 45781 | E8: =IF(D8<B8,B8,D8) -> 45781 | F8: =E8-C8 -> 20 | G8: =IF(Data!F5<=7,1,0) -> 0 | H8: =TEXT(C8,"MM-YYYY") -> 04-2025 | I8: ="Q"&ROUNDUP(MONTH(H8)/3,0)&"-"&YEAR(H8) -> Q2-2025 | J8: =_xlfn.MINIFS(C:C,M:M,M8) -> 44945 | K8: =TEXT(J8,"MM-YYYY") -> 01-2023 | L8: Europe | M8: United Kingdom | N8: Birmingham | O8: =IF(N8="",_xlfn.XLOOKUP(M8,M:M,N:N),N8) -> Birmingham | P8: Enterprise | Q8: Marketplace | R8: =IF(Q8="",_xlfn.XLOOKUP(M8,M:M,Q:Q),Q8) -> Marketplace | S8: K. Singh | T8: =IF(S8="",_xlfn.XLOOKUP(L8,L:L,S:S),S8) -> K. Singh | U8: Monitors | V8: =IF(AA8<815.0987,"Low",IF(AA8<1640.058,"Medium","High")) -> High | W8: MON-6962 | X8: =IF(AK8<=80%,"A",IF(AK8<=95%,"B","C")) -> A | Y8: 1413.87 | Z8: 3275 | AA8: =ABS(Z8) -> 3275 | AB8: 0.255 | AC8: =MIN(AB8,30%) -> 0.255 | AD8: =IF(AC8>20%,1,0) -> 1 | AE8: 38 | AF8: =AA8*AE8*(1-AC8) -> 92715.25 | AG8: =Y8*AE8 -> 53727.06 | AH8: =ABS(AF8-AG8) -> 38988.19 | AI8: =IF(AF8=0,0,AH8/AF8) -> 0.4205154 | AJ8: =AJ7+AF8 -> 580097.5 | AK8: =AJ8/SUM(AF:AF) -> 0.052997423 | AL8: =MIN(AC8,'What-If Analysis'!$B$2) -> 0.2 | AM8: =AE8*(1+'What-If Analysis'!$B$3) -> 49.4 | AN8: =Y8*(1+'What-If Analysis'!$B$4) -> 1555.257 | AO8: =AA8*AM8*(1-AL8) -> 129428
A9: ORD-2024-948800 | B9: 45378 | C9: =IF(D9<B9,D9,B9) -> 45378 | D9: 45393 | E9: =IF(D9<B9,B9,D9) -> 45393 | F9: =E9-C9 -> 15 | G9: =IF(Data!F11<=7,1,0) -> 0 | H9: =TEXT(C9,"MM-YYYY") -> 03-2024 | I9: ="Q"&ROUNDUP(MONTH(H9)/3,0)&"-"&YEAR(H9) -> Q1-2024 | J9: =_xlfn.MINIFS(C:C,M:M,M9) -> 44939 | K9: =TEXT(J9,"MM-YYYY") -> 01-2023 | L9: Americas | M9: USA | N9: San Francisco | O9: =IF(N9="",_xlfn.XLOOKUP(M9,M:M,N:N),N9) -> San Francisco | P9: Small Business | Q9: Direct | R9: =IF(Q9="",_xlfn.XLOOKUP(M9,M:M,Q:Q),Q9) -> Direct | S9: O. Wang | T9: =IF(S9="",_xlfn.XLOOKUP(L9,L:L,S:S),S9) -> O. Wang | U9: Networking | V9: =IF(AA9<815.0987,"Low",IF(AA9<1640.058,"Medium","High")) -> High | W9: NET-5523 | X9: =IF(AK9<=80%,"A",IF(AK9<=95%,"B","C")) -> A | Y9: 1338.35 | Z9: 2247.14 | AA9: =ABS(Z9) -> 2247.14 | AB9: 0.115 | AC9: =MIN(AB9,30%) -> 0.115 | AD9: =IF(AC9>20%,1,0) -> 0 | AE9: 40 | AF9: =AA9*AE9*(1-AC9) -> 79548.756 | AG9: =Y9*AE9 -> 53534 | AH9: =ABS(AF9-AG9) -> 26014.756 | AI9: =IF(AF9=0,0,AH9/AF9) -> 0.32702907 | AJ9: =AJ8+AF9 -> 659646.25 | AK9: =AJ9/SUM(AF:AF) -> 0.060264959 | AL9: =MIN(AC9,'What-If Analysis'!$B$2) -> 0.115 | AM9: =AE9*(1+'What-If Analysis'!$B$3) -> 52 | AN9: =Y9*(1+'What-If Analysis'!$B$4) -> 1472.185 | AO9: =AA9*AM9*(1-AL9) -> 103413.38
A10: ORD-2024-508213 | B10: 45618 | C10: =IF(D10<B10,D10,B10) -> 45618 | D10: 45641 | E10: =IF(D10<B10,B10,D10) -> 45641 | F10: =E10-C10 -> 23 | G10: =IF(Data!F8<=7,1,0) -> 0 | H10: =TEXT(C10,"MM-YYYY") -> 11-2024 | I10: ="Q"&ROUNDUP(MONTH(H10)/3,0)&"-"&YEAR(H10) -> Q4-2024 | J10: =_xlfn.MINIFS(C:C,M:M,M10) -> 44946 | K10: =TEXT(J10,"MM-YYYY") -> 01-2023 | L10: Africa | M10: Kenya | N10: Mombasa | O10: =IF(N10="",_xlfn.XLOOKUP(M10,M:M,N:N),N10) -> Mombasa | P10: Non-Profit | Q10: Distributor | R10: =IF(Q10="",_xlfn.XLOOKUP(M10,M:M,Q:Q),Q10) -> Distributor | S10: C. Otieno | T10: =IF(S10="",_xlfn.XLOOKUP(L10,L:L,S:S),S10) -> C. Otieno | U10: Components | V10: =IF(AA10<815.0987,"Low",IF(AA10<1640.058,"Medium","High")) -> High | W10: CMP-3938 | X10: =IF(AK10<=80%,"A",IF(AK10<=95%,"B","C")) -> A | Y10: 1335.76 | Z10: 2665.91 | AA10: =ABS(Z10) -> 2665.91 | AB10: 0.211 | AC10: =MIN(AB10,30%) -> 0.211 | AD10: =IF(AC10>20%,1,0) -> 1 | AE10: 40 | AF10: =AA10*AE10*(1-AC10) -> 84136.12 | AG10: =Y10*AE10 -> 53430.4 | AH10: =ABS(AF10-AG10) -> 30705.72 | AI10: =IF(AF10=0,0,AH10/AF10) -> 0.36495289 | AJ10: =AJ9+AF10 -> 743782.37 | AK10: =AJ10/SUM(AF:AF) -> 0.067951593 | AL10: =MIN(AC10,'What-If Analysis'!$B$2) -> 0.2 | AM10: =AE10*(1+'What-If Analysis'!$B$3) -> 52 | AN10: =Y10*(1+'What-If Analysis'!$B$4) -> 1469.336 | AO10: =AA10*AM10*(1-AL10) -> 110901.86
A11: ORD-2024-713332 | B11: 45448 | C11: =IF(D11<B11,D11,B11) -> 45448 | D11: 45466 | E11: =IF(D11<B11,B11,D11) -> 45466 | F11: =E11-C11 -> 18 | G11: =IF(Data!F22<=7,1,0) -> 1 | H11: =TEXT(C11,"MM-YYYY") -> 06-2024 | I11: ="Q"&ROUNDUP(MONTH(H11)/3,0)&"-"&YEAR(H11) -> Q2-2024 | J11: =_xlfn.MINIFS(C:C,M:M,M11) -> 44946 | K11: =TEXT(J11,"MM-YYYY") -> 01-2023 | L11: Africa | M11: Kenya | N11: Nairobi | O11: =IF(N11="",_xlfn.XLOOKUP(M11,M:M,N:N),N11) -> Nairobi | P11: Consumer | Q11: Distributor | R11: =IF(Q11="",_xlfn.XLOOKUP(M11,M:M,Q:Q),Q11) -> Distributor | S11: D. Smith | T11: =IF(S11="",_xlfn.XLOOKUP(L11,L:L,S:S),S11) -> D. Smith | U11: Laptops | V11: =IF(AA11<815.0987,"Low",IF(AA11<1640.058,"Medium","High")) -> Medium | W11: LAP-1739 | X11: =IF(AK11<=80%,"A",IF(AK11<=95%,"B","C")) -> A | Y11: 1208.74 | Z11: 1594.78 | AA11: =ABS(Z11) -> 1594.78 | AB11: 0.059 | AC11: =MIN(AB11,30%) -> 0.059 | AD11: =IF(AC11>20%,1,0) -> 0 | AE11: 39 | AF11: =AA11*AE11*(1-AC11) -> 58526.831 | AG11: =Y11*AE11 -> 47140.86 | AH11: =ABS(AF11-AG11) -> 11385.971 | AI11: =IF(AF11=0,0,AH11/AF11) -> 0.19454276 | AJ11: =AJ10+AF11 -> 802309.2 | AK11: =AJ11/SUM(AF:AF) -> 0.073298576 | AL11: =MIN(AC11,'What-If Analysis'!$B$2) -> 0.059 | AM11: =AE11*(1+'What-If Analysis'!$B$3) -> 50.7 | AN11: =Y11*(1+'What-If Analysis'!$B$4) -> 1329.614 | AO11: =AA11*AM11*(1-AL11) -> 76084.881
A12: ORD-2023-594955 | B12: 45097 | C12: =IF(D12<B12,D12,B12) -> 45097 | D12: 45115 | E12: =IF(D12<B12,B12,D12) -> 45115 | F12: =E12-C12 -> 18 | G12: =IF(Data!F37<=7,1,0) -> 0 | H12: =TEXT(C12,"MM-YYYY") -> 06-2023 | I12: ="Q"&ROUNDUP(MONTH(H12)/3,0)&"-"&YEAR(H12) -> Q2-2023 | J12: =_xlfn.MINIFS(C:C,M:M,M12) -> 44939 | K12: =TEXT(J12,"MM-YYYY") -> 01-2023 | L12: Americas | M12: USA | N12: New York | O12: =IF(N12="",_xlfn.XLOOKUP(M12,M:M,N:N),N12) -> New York | P12: Consumer | Q12: Marketplace | R12: =IF(Q12="",_xlfn.XLOOKUP(M12,M:M,Q:Q),Q12) -> Marketplace | S12: O. Wang | T12: =IF(S12="",_xlfn.XLOOKUP(L12,L:L,S:S),S12) -> O. Wang | U12: Networking | V12: =IF(AA12<815.0987,"Low",IF(AA12<1640.058,"Medium","High")) -> Medium | W12: NET-3828 | X12: =IF(AK12<=80%,"A",IF(AK12<=95%,"B","C")) -> A | Y12: 1145.53 | Z12: 1278.3 | AA12: =ABS(Z12) -> 1278.3 | AB12: 0.09 | AC12: =MIN(AB12,30%) -> 0.09 | AD12: =IF(AC12>20%,1,0) -> 0 | AE12: 41 | AF12: =AA12*AE12*(1-AC12) -> 47693.373 | AG12: =Y12*AE12 -> 46966.73 | AH12: =ABS(AF12-AG12) -> 726.643 | AI12: =IF(AF12=0,0,AH12/AF12) -> 0.015235723 | AJ12: =AJ11+AF12 -> 850002.58 | AK12: =AJ12/SUM(AF:AF) -> 0.077655819 | AL12: =MIN(AC12,'What-If Analysis'!$B$2) -> 0.09 | AM12: =AE12*(1+'What-If Analysis'!$B$3) -> 53.3 | AN12: =Y12*(1+'What-If Analysis'!$B$4) -> 1260.083 | AO12: =AA12*AM12*(1-AL12) -> 62001.385
A13: ORD-2023-835010 | B13: 45008 | C13: =IF(D13<B13,D13,B13) -> 45008 | D13: 45031 | E13: =IF(D13<B13,B13,D13) -> 45031 | F13: =E13-C13 -> 23 | G13: =IF(Data!F27<=7,1,0) -> 0 | H13: =TEXT(C13,"MM-YYYY") -> 03-2023 | I13: ="Q"&ROUNDUP(MONTH(H13)/3,0)&"-"&YEAR(H13) -> Q1-2023 | J13: =_xlfn.MINIFS(C:C,M:M,M13) -> 44946 | K13: =TEXT(J13,"MM-YYYY") -> 01-2023 | L13: Africa | M13: Kenya | N13: Mombasa | O13: =IF(N13="",_xlfn.XLOOKUP(M13,M:M,N:N),N13) -> Mombasa | P13: Small Business | Q13: Retail | R13: =IF(Q13="",_xlfn.XLOOKUP(M13,M:M,Q:Q),Q13) -> Retail | S13: C. Otieno | T13: =IF(S13="",_xlfn.XLOOKUP(L13,L:L,S:S),S13) -> C. Otieno | U13: Accessories | V13: =IF(AA13<815.0987,"Low",IF(AA13<1640.058,"Medium","High")) -> Medium | W13: ACC-2988 | X13: =IF(AK13<=80%,"A",IF(AK13<=95%,"B","C")) -> A | Y13: 875.36 | Z13: 1178.62 | AA13: =ABS(Z13) -> 1178.62 | AB13: 0.151 | AC13: =MIN(AB13,30%) -> 0.151 | AD13: =IF(AC13>20%,1,0) -> 0 | AE13: 53 | AF13: =AA13*AE13*(1-AC13) -> 53034.364 | AG13: =Y13*AE13 -> 46394.08 | AH13: =ABS(AF13-AG13) -> 6640.2841 | AI13: =IF(AF13=0,0,AH13/AF13) -> 0.1252072 | AJ13: =AJ12+AF13 -> 903036.94 | AK13: =AJ13/SUM(AF:AF) -> 0.082501013 | AL13: =MIN(AC13,'What-If Analysis'!$B$2) -> 0.151 | AM13: =AE13*(1+'What-If Analysis'!$B$3) -> 68.9 | AN13: =Y13*(1+'What-If Analysis'!$B$4) -> 962.896 | AO13: =AA13*AM13*(1-AL13) -> 68944.673
A14: ORD-2024-964950 | B14: 45575 | C14: =IF(D14<B14,D14,B14) -> 45575 | D14: 45576 | E14: =IF(D14<B14,B14,D14) -> 45576 | F14: =E14-C14 -> 1 | G14: =IF(Data!F33<=7,1,0) -> 0 | H14: =TEXT(C14,"MM-YYYY") -> 10-2024 | I14: ="Q"&ROUNDUP(MONTH(H14)/3,0)&"-"&YEAR(H14) -> Q4-2024 | J14: =_xlfn.MINIFS(C:C,M:M,M14) -> 44945 | K14: =TEXT(J14,"MM-YYYY") -> 01-2023 | L14: Europe | M14: United Kingdom | N14: Manchester | O14: =IF(N14="",_xlfn.XLOOKUP(M14,M:M,N:N),N14) -> Manchester | P14: Non-Profit | Q14: Distributor | R14: =IF(Q14="",_xlfn.XLOOKUP(M14,M:M,Q:Q),Q14) -> Distributor | S14: L. Okafor | T14: =IF(S14="",_xlfn.XLOOKUP(L14,L:L,S:S),S14) -> L. Okafor | U14: Components | V14: =IF(AA14<815.0987,"Low",IF(AA14<1640.058,"Medium","High")) -> High | W14: CMP-8127 | X14: =IF(AK14<=80%,"A",IF(AK14<=95%,"B","C")) -> A | Y14: 1389.46 | Z14: 1784.7 | AA14: =ABS(Z14) -> 1784.7 | AB14: 0.146 | AC14: =MIN(AB14,30%) -> 0.146 | AD14: =IF(AC14>20%,1,0) -> 0 | AE14: 33 | AF14: =AA14*AE14*(1-AC14) -> 50296.415 | AG14: =Y14*AE14 -> 45852.18 | AH14: =ABS(AF14-AG14) -> 4444.2354 | AI14: =IF(AF14=0,0,AH14/AF14) -> 0.088360878 | AJ14: =AJ13+AF14 -> 953333.36 | AK14: =AJ14/SUM(AF:AF) -> 0.087096069 | AL14: =MIN(AC14,'What-If Analysis'!$B$2) -> 0.146 | AM14: =AE14*(1+'What-If Analysis'!$B$3) -> 42.9 | AN14: =Y14*(1+'What-If Analysis'!$B$4) -> 1528.406 | AO14: =AA14*AM14*(1-AL14) -> 65385.34
A15: ORD-2024-548345 | B15: 45426 | C15: =IF(D15<B15,D15,B15) -> 45426 | D15: 45440 | E15: =IF(D15<B15,B15,D15) -> 45440 | F15: =E15-C15 -> 14 | G15: =IF(Data!F3<=7,1,0) -> 0 | H15: =TEXT(C15,"MM-YYYY") -> 05-2024 | I15: ="Q"&ROUNDUP(MONTH(H15)/3,0)&"-"&YEAR(H15) -> Q2-2024 | J15: =_xlfn.MINIFS(C:C,M:M,M15) -> 44945 | K15: =TEXT(J15,"MM-YYYY") -> 01-2023 | L15: Europe | M15: United Kingdom | N15: Birmingham | O15: =IF(N15="",_xlfn.XLOOKUP(M15,M:M,N:N),N15) -> Birmingham | P15: Consumer | Q15: Retail | R15: =IF(Q15="",_xlfn.XLOOKUP(M15,M:M,Q:Q),Q15) -> Retail | S15: B. Chen | T15: =IF(S15="",_xlfn.XLOOKUP(L15,L:L,S:S),S15) -> B. Chen | U15: Networking | V15: =IF(AA15<815.0987,"Low",IF(AA15<1640.058,"Medium","High")) -> High | W15: NET-2365 | X15: =IF(AK15<=80%,"A",IF(AK15<=95%,"B","C")) -> A | Y15: 1421.14 | Z15: 3524 | AA15: =ABS(Z15) -> 3524 | AB15: 0 | AC15: =MIN(AB15,30%) -> 0 | AD15: =IF(AC15>20%,1,0) -> 0 | AE15: 31 | AF15: =AA15*AE15*(1-AC15) -> 109244 | AG15: =Y15*AE15 -> 44055.34 | AH15: =ABS(AF15-AG15) -> 65188.66 | AI15: =IF(AF15=0,0,AH15/AF15) -> 0.59672531 | AJ15: =AJ14+AF15 -> 1062577.4 | AK15: =AJ15/SUM(AF:AF) -> 0.097076547 | AL15: =MIN(AC15,'What-If Analysis'!$B$2) -> 0 | AM15: =AE15*(1+'What-If Analysis'!$B$3) -> 40.3 | AN15: =Y15*(1+'What-If Analysis'!$B$4) -> 1563.254 | AO15: =AA15*AM15*(1-AL15) -> 142017.2
A16: ORD-2024-901115 | B16: 45498 | C16: =IF(D16<B16,D16,B16) -> 45498 | D16: 45506 | E16: =IF(D16<B16,B16,D16) -> 45506 | F16: =E16-C16 -> 8 | G16: =IF(Data!F12<=7,1,0) -> 0 | H16: =TEXT(C16,"MM-YYYY") -> 07-2024 | I16: ="Q"&ROUNDUP(MONTH(H16)/3,0)&"-"&YEAR(H16) -> Q3-2024 | J16: =_xlfn.MINIFS(C:C,M:M,M16) -> 44928 | K16: =TEXT(J16,"MM-YYYY") -> 01-2023 | L16: Americas | M16: Canada | N16: Montreal | O16: =IF(N16="",_xlfn.XLOOKUP(M16,M:M,N:N),N16) -> Montreal | P16: Consumer | Q16: Direct | R16: =IF(Q16="",_xlfn.XLOOKUP(M16,M:M,Q:Q),Q16) -> Direct | S16: J. Njeri | T16: =IF(S16="",_xlfn.XLOOKUP(L16,L:L,S:S),S16) -> J. Njeri | U16: Accessories | V16: =IF(AA16<815.0987,"Low",IF(AA16<1640.058,"Medium","High")) -> High | W16: ACC-6626 | X16: =IF(AK16<=80%,"A",IF(AK16<=95%,"B","C")) -> A | Y16: 986.81 | Z16: 2050.31 | AA16: =ABS(Z16) -> 2050.31 | AB16: 0.103 | AC16: =MIN(AB16,30%) -> 0.103 | AD16: =IF(AC16>20%,1,0) -> 0 | AE16: 43 | AF16: =AA16*AE16*(1-AC16) -> 79082.507 | AG16: =Y16*AE16 -> 42432.83 | AH16: =ABS(AF16-AG16) -> 36649.677 | AI16: =IF(AF16=0,0,AH16/AF16) -> 0.46343595 | AJ16: =AJ15+AF16 -> 1141659.9 | AK16: =AJ16/SUM(AF:AF) -> 0.10430149 | AL16: =MIN(AC16,'What-If Analysis'!$B$2) -> 0.103 | AM16: =AE16*(1+'What-If Analysis'!$B$3) -> 55.9 | AN16: =Y16*(1+'What-If Analysis'!$B$4) -> 1085.491 | AO16: =AA16*AM16*(1-AL16) -> 102807.26
A17: ORD-2025-997421 | B17: 45798 | C17: =IF(D17<B17,D17,B17) -> 45798 | D17: 45817 | E17: =IF(D17<B17,B17,D17) -> 45817 | F17: =E17-C17 -> 19 | G17: =IF(Data!F20<=7,1,0) -> 1 | H17: =TEXT(C17,"MM-YYYY") -> 05-2025 | I17: ="Q"&ROUNDUP(MONTH(H17)/3,0)&"-"&YEAR(H17) -> Q2-2025 | J17: =_xlfn.MINIFS(C:C,M:M,M17) -> 44955 | K17: =TEXT(J17,"MM-YYYY") -> 01-2023 | L17: Americas | M17: Brazil | N17: São Paulo | O17: =IF(N17="",_xlfn.XLOOKUP(M17,M:M,N:N),N17) -> São Paulo | P17: Non-Profit | Q17: Online | R17: =IF(Q17="",_xlfn.XLOOKUP(M17,M:M,Q:Q),Q17) -> Online | S17: A. Patel | T17: =IF(S17="",_xlfn.XLOOKUP(L17,L:L,S:S),S17) -> A. Patel | U17: Components | V17: =IF(AA17<815.0987,"Low",IF(AA17<1640.058,"Medium","High")) -> High | W17: CMP-3731 | X17: =IF(AK17<=80%,"A",IF(AK17<=95%,"B","C")) -> A | Y17: 1331.38 | Z17: 2309.56 | AA17: =ABS(Z17) -> 2309.56 | AB17: 0.149 | AC17: =MIN(AB17,30%) -> 0.149 | AD17: =IF(AC17>20%,1,0) -> 0 | AE17: 31 | AF17: =AA17*AE17*(1-AC17) -> 60928.502 | AG17: =Y17*AE17 -> 41272.78 | AH17: =ABS(AF17-AG17) -> 19655.722 | AI17: =IF(AF17=0,0,AH17/AF17) -> 0.32260308 | AJ17: =AJ16+AF17 -> 1202588.4 | AK17: =AJ17/SUM(AF:AF) -> 0.10986788 | AL17: =MIN(AC17,'What-If Analysis'!$B$2) -> 0.149 | AM17: =AE17*(1+'What-If Analysis'!$B$3) -> 40.3 | AN17: =Y17*(1+'What-If Analysis'!$B$4) -> 1464.518 | AO17: =AA17*AM17*(1-AL17) -> 79207.053
A18: ORD-2024-584090 | B18: 45450 | C18: =IF(D18<B18,D18,B18) -> 45450 | D18: 45469 | E18: =IF(D18<B18,B18,D18) -> 45469 | F18: =E18-C18 -> 19 | G18: =IF(Data!F18<=7,1,0) -> 0 | H18: =TEXT(C18,"MM-YYYY") -> 06-2024 | I18: ="Q"&ROUNDUP(MONTH(H18)/3,0)&"-"&YEAR(H18) -> Q2-2024 | J18: =_xlfn.MINIFS(C:C,M:M,M18) -> 44947 | K18: =TEXT(J18,"MM-YYYY") -> 01-2023 | L18: Europe | M18: Germany | N18: Berlin | O18: =IF(N18="",_xlfn.XLOOKUP(M18,M:M,N:N),N18) -> Berlin | P18: Non-Profit | Q18: Marketplace | R18: =IF(Q18="",_xlfn.XLOOKUP(M18,M:M,Q:Q),Q18) -> Marketplace | S18: M. Rossi | T18: =IF(S18="",_xlfn.XLOOKUP(L18,L:L,S:S),S18) -> M. Rossi | U18: Components | V18: =IF(AA18<815.0987,"Low",IF(AA18<1640.058,"Medium","High")) -> High | W18: CMP-2040 | X18: =IF(AK18<=80%,"A",IF(AK18<=95%,"B","C")) -> A | Y18: 1064.32 | Z18: 1848.39 | AA18: =ABS(Z18) -> 1848.39 | AB18: 0.073 | AC18: =MIN(AB18,30%) -> 0.073 | AD18: =IF(AC18>20%,1,0) -> 0 | AE18: 38 | AF18: =AA18*AE18*(1-AC18) -> 65111.386 | AG18: =Y18*AE18 -> 40444.16 | AH18: =ABS(AF18-AG18) -> 24667.226 | AI18: =IF(AF18=0,0,AH18/AF18) -> 0.37884658 | AJ18: =AJ17+AF18 -> 1267699.8 | AK18: =AJ18/SUM(AF:AF) -> 0.11581643 | AL18: =MIN(AC18,'What-If Analysis'!$B$2) -> 0.073 | AM18: =AE18*(1+'What-If Analysis'!$B$3) -> 49.4 | AN18: =Y18*(1+'What-If Analysis'!$B$4) -> 1170.752 | AO18: =AA18*AM18*(1-AL18) -> 84644.802
A19: ORD-2023-368449 | B19: 45208 | C19: =IF(D19<B19,D19,B19) -> 45208 | D19: 45225 | E19: =IF(D19<B19,B19,D19) -> 45225 | F19: =E19-C19 -> 17 | G19: =IF(Data!F29<=7,1,0) -> 1 | H19: =TEXT(C19,"MM-YYYY") -> 10-2023 | I19: ="Q"&ROUNDUP(MONTH(H19)/3,0)&"-"&YEAR(H19) -> Q4-2023 | J19: =_xlfn.MINIFS(C:C,M:M,M19) -> 44938 | K19: =TEXT(J19,"MM-YYYY") -> 01-2023 | L19: Asia | M19: China | N19: Shanghai | O19: =IF(N19="",_xlfn.XLOOKUP(M19,M:M,N:N),N19) -> Shanghai | P19: Consumer | Q19: Marketplace | R19: =IF(Q19="",_xlfn.XLOOKUP(M19,M:M,Q:Q),Q19) -> Marketplace | S19: C. Otieno | T19: =IF(S19="",_xlfn.XLOOKUP(L19,L:L,S:S),S19) -> C. Otieno | U19: Components | V19: =IF(AA19<815.0987,"Low",IF(AA19<1640.058,"Medium","High")) -> High | W19: CMP-2096 | X19: =IF(AK19<=80%,"A",IF(AK19<=95%,"B","C")) -> A | Y19: 1132.03 | Z19: 2137.21 | AA19: =ABS(Z19) -> 2137.21 | AB19: 0.357 | AC19: =MIN(AB19,30%) -> 0.3 | AD19: =IF(AC19>20%,1,0) -> 1 | AE19: 35 | AF19: =AA19*AE19*(1-AC19) -> 52361.645 | AG19: =Y19*AE19 -> 39621.05 | AH19: =ABS(AF19-AG19) -> 12740.595 | AI19: =IF(AF19=0,0,AH19/AF19) -> 0.24331923 | AJ19: =AJ18+AF19 -> 1320061.4 | AK19: =AJ19/SUM(AF:AF) -> 0.12060016 | AL19: =MIN(AC19,'What-If Analysis'!$B$2) -> 0.2 | AM19: =AE19*(1+'What-If Analysis'!$B$3) -> 45.5 | AN19: =Y19*(1+'What-If Analysis'!$B$4) -> 1245.233 | AO19: =AA19*AM19*(1-AL19) -> 77794.444
A20: ORD-2023-159821 | B20: 45108 | C20: =IF(D20<B20,D20,B20) -> 45108 | D20: 45115 | E20: =IF(D20<B20,B20,D20) -> 45115 | F20: =E20-C20 -> 7 | G20: =IF(Data!F9<=7,1,0) -> 0 | H20: =TEXT(C20,"MM-YYYY") -> 07-2023 | I20: ="Q"&ROUNDUP(MONTH(H20)/3,0)&"-"&YEAR(H20) -> Q3-2023 | J20: =_xlfn.MINIFS(C:C,M:M,M20) -> 44939 | K20: =TEXT(J20,"MM-YYYY") -> 01-2023 | L20: Africa | M20: Nigeria | N20: Port Harcourt | O20: =IF(N20="",_xlfn.XLOOKUP(M20,M:M,N:N),N20) -> Port Harcourt | P20: Corporate | Q20: Retail | R20: =IF(Q20="",_xlfn.XLOOKUP(M20,M:M,Q:Q),Q20) -> Retail | S20: A. Patel | T20: =IF(S20="",_xlfn.XLOOKUP(L20,L:L,S:S),S20) -> A. Patel | U20: Laptops | V20: =IF(AA20<815.0987,"Low",IF(AA20<1640.058,"Medium","High")) -> High | W20: LAP-3904 | X20: =IF(AK20<=80%,"A",IF(AK20<=95%,"B","C")) -> A | Y20: 834.26 | Z20: 1780.56 | AA20: =ABS(Z20) -> 1780.56 | AB20: 0.014 | AC20: =MIN(AB20,30%) -> 0.014 | AD20: =IF(AC20>20%,1,0) -> 0 | AE20: 47 | AF20: =AA20*AE20*(1-AC20) -> 82514.712 | AG20: =Y20*AE20 -> 39210.22 | AH20: =ABS(AF20-AG20) -> 43304.492 | AI20: =IF(AF20=0,0,AH20/AF20) -> 0.52480934 | AJ20: =AJ19+AF20 -> 1402576.1 | AK20: =AJ20/SUM(AF:AF) -> 0.12813867 | AL20: =MIN(AC20,'What-If Analysis'!$B$2) -> 0.014 | AM20: =AE20*(1+'What-If Analysis'!$B$3) -> 61.1 | AN20: =Y20*(1+'What-If Analysis'!$B$4) -> 917.686 | AO20: =AA20*AM20*(1-AL20) -> 107269.12
A21: ORD-2023-159379 | B21: 44965 | C21: =IF(D21<B21,D21,B21) -> 44965 | D21: 44968 | E21: =IF(D21<B21,B21,D21) -> 44968 | F21: =E21-C21 -> 3 | G21: =IF(Data!F21<=7,1,0) -> 1 | H21: =TEXT(C21,"MM-YYYY") -> 02-2023 | I21: ="Q"&ROUNDUP(MONTH(H21)/3,0)&"-"&YEAR(H21) -> Q1-2023 | J21: =_xlfn.MINIFS(C:C,M:M,M21) -> 44933 | K21: =TEXT(J21,"MM-YYYY") -> 01-2023 | L21: Africa | M21: South Africa | N21: Cape Town | O21: =IF(N21="",_xlfn.XLOOKUP(M21,M:M,N:N),N21) -> Cape Town | P21: Corporate | Q21: Direct | R21: =IF(Q21="",_xlfn.XLOOKUP(M21,M:M,Q:Q),Q21) -> Direct | S21: M. Rossi | T21: =IF(S21="",_xlfn.XLOOKUP(L21,L:L,S:S),S21) -> M. Rossi | U21: Networking | V21: =IF(AA21<815.0987,"Low",IF(AA21<1640.058,"Medium","High")) -> High | W21: NET-5018 | X21: =IF(AK21<=80%,"A",IF(AK21<=95%,"B","C")) -> A | Y21: 1410.05 | Z21: 2763.95 | AA21: =ABS(Z21) -> 2763.95 | AB21: 0.161 | AC21: =MIN(AB21,30%) -> 0.161 | AD21: =IF(AC21>20%,1,0) -> 0 | AE21: 26 | AF21: =AA21*AE21*(1-AC21) -> 60292.805 | AG21: =Y21*AE21 -> 36661.3 | AH21: =ABS(AF21-AG21) -> 23631.505 | AI21: =IF(AF21=0,0,AH21/AF21) -> 0.39194569 | AJ21: =AJ20+AF21 -> 1462868.9 | AK21: =AJ21/SUM(AF:AF) -> 0.13364699 | AL21: =MIN(AC21,'What-If Analysis'!$B$2) -> 0.161 | AM21: =AE21*(1+'What-If Analysis'!$B$3) -> 33.8 | AN21: =Y21*(1+'What-If Analysis'!$B$4) -> 1551.055 | AO21: =AA21*AM21*(1-AL21) -> 78380.647
A22: ORD-2023-974506 | B22: 45288 | C22: =IF(D22<B22,D22,B22) -> 45288 | D22: 45292 | E22: =IF(D22<B22,B22,D22) -> 45292 | F22: =E22-C22 -> 4 | G22: =IF(Data!F16<=7,1,0) -> 0 | H22: =TEXT(C22,"MM-YYYY") -> 12-2023 | I22: ="Q"&ROUNDUP(MONTH(H22)/3,0)&"-"&YEAR(H22) -> Q4-2023 | J22: =_xlfn.MINIFS(C:C,M:M,M22) -> 44933 | K22: =TEXT(J22,"MM-YYYY") -> 01-2023 | L22: Africa | M22: South Africa | N22: Cape Town | O22: =IF(N22="",_xlfn.XLOOKUP(M22,M:M,N:N),N22) -> Cape Town | P22: Education | Q22: Distributor | R22: =IF(Q22="",_xlfn.XLOOKUP(M22,M:M,Q:Q),Q22) -> Distributor | S22: A. Patel | T22: =IF(S22="",_xlfn.XLOOKUP(L22,L:L,S:S),S22) -> A. Patel | U22: Printers | V22: =IF(AA22<815.0987,"Low",IF(AA22<1640.058,"Medium","High")) -> High | W22: PRN-1654 | X22: =IF(AK22<=80%,"A",IF(AK22<=95%,"B","C")) -> A | Y22: 1141.8 | Z22: 2318.74 | AA22: =ABS(Z22) -> 2318.74 | AB22: 0.107 | AC22: =MIN(AB22,30%) -> 0.107 | AD22: =IF(AC22>20%,1,0) -> 0 | AE22: 32 | AF22: =AA22*AE22*(1-AC22) -> 66260.314 | AG22: =Y22*AE22 -> 36537.6 | AH22: =ABS(AF22-AG22) -> 29722.714 | AI22: =IF(AF22=0,0,AH22/AF22) -> 0.44857491 | AJ22: =AJ21+AF22 -> 1529129.2 | AK22: =AJ22/SUM(AF:AF) -> 0.1397005 | AL22: =MIN(AC22,'What-If Analysis'!$B$2) -> 0.107 | AM22: =AE22*(1+'What-If Analysis'!$B$3) -> 41.6 | AN22: =Y22*(1+'What-If Analysis'!$B$4) -> 1255.98 | AO22: =AA22*AM22*(1-AL22) -> 86138.409
A23: ORD-2023-586275 | B23: 44946 | C23: =IF(D23<B23,D23,B23) -> 44946 | D23: 44960 | E23: =IF(D23<B23,B23,D23) -> 44960 | F23: =E23-C23 -> 14 | G23: =IF(Data!F36<=7,1,0) -> 0 | H23: =TEXT(C23,"MM-YYYY") -> 01-2023 | I23: ="Q"&ROUNDUP(MONTH(H23)/3,0)&"-"&YEAR(H23) -> Q1-2023 | J23: =_xlfn.MINIFS(C:C,M:M,M23) -> 44946 | K23: =TEXT(J23,"MM-YYYY") -> 01-2023 | L23: Africa | M23: Kenya | N23: Kisumu | O23: =IF(N23="",_xlfn.XLOOKUP(M23,M:M,N:N),N23) -> Kisumu | P23: Corporate | Q23: Retail | R23: =IF(Q23="",_xlfn.XLOOKUP(M23,M:M,Q:Q),Q23) -> Retail | S23: M. Rossi | T23: =IF(S23="",_xlfn.XLOOKUP(L23,L:L,S:S),S23) -> M. Rossi | U23: Networking | V23: =IF(AA23<815.0987,"Low",IF(AA23<1640.058,"Medium","High")) -> Medium | W23: NET-6036 | X23: =IF(AK23<=80%,"A",IF(AK23<=95%,"B","C")) -> A | Y23: 884.36 | Z23: 1545.34 | AA23: =ABS(Z23) -> 1545.34 | AB23: 0.243 | AC23: =MIN(AB23,30%) -> 0.243 | AD23: =IF(AC23>20%,1,0) -> 1 | AE23: 41 | AF23: =AA23*AE23*(1-AC23) -> 47962.718 | AG23: =Y23*AE23 -> 36258.76 | AH23: =ABS(AF23-AG23) -> 11703.958 | AI23: =IF(AF23=0,0,AH23/AF23) -> 0.24402199 | AJ23: =AJ22+AF23 -> 1577091.9 | AK23: =AJ23/SUM(AF:AF) -> 0.14408235 | AL23: =MIN(AC23,'What-If Analysis'!$B$2) -> 0.2 | AM23: =AE23*(1+'What-If Analysis'!$B$3) -> 53.3 | AN23: =Y23*(1+'What-If Analysis'!$B$4) -> 972.796 | AO23: =AA23*AM23*(1-AL23) -> 65893.298
A24: ORD-2023-676553 | B24: 45066 | C24: =IF(D24<B24,D24,B24) -> 45066 | D24: 45096 | E24: =IF(D24<B24,B24,D24) -> 45096 | F24: =E24-C24 -> 30 | G24: =IF(Data!F177<=7,1,0) -> 0 | H24: =TEXT(C24,"MM-YYYY") -> 05-2023 | I24: ="Q"&ROUNDUP(MONTH(H24)/3,0)&"-"&YEAR(H24) -> Q2-2023 | J24: =_xlfn.MINIFS(C:C,M:M,M24) -> 44955 | K24: =TEXT(J24,"MM-YYYY") -> 01-2023 | L24: Asia | M24: India | N24: Delhi | O24: =IF(N24="",_xlfn.XLOOKUP(M24,M:M,N:N),N24) -> Delhi | P24: Non-Profit | Q24: Marketplace | R24: =IF(Q24="",_xlfn.XLOOKUP(M24,M:M,Q:Q),Q24) -> Marketplace | S24: H. Kim | T24: =IF(S24="",_xlfn.XLOOKUP(L24,L:L,S:S),S24) -> H. Kim | U24: Laptops | V24: =IF(AA24<815.0987,"Low",IF(AA24<1640.058,"Medium","High")) -> Medium | W24: LAP-2806 | X24: =IF(AK24<=80%,"A",IF(AK24<=95%,"B","C")) -> A | Y24: 1161.2 | Z24: 878.73 | AA24: =ABS(Z24) -> 878.73 | AB24: 0.19 | AC24: =MIN(AB24,30%) -> 0.19 | AD24: =IF(AC24>20%,1,0) -> 0 | AE24: 31 | AF24: =AA24*AE24*(1-AC24) -> 22064.91 | AG24: =Y24*AE24 -> 35997.2 | AH24: =ABS(AF24-AG24) -> 13932.29 | AI24: =IF(AF24=0,0,AH24/AF24) -> 0.6314229 | AJ24: =AJ23+AF24 -> 1599156.9 | AK24: =AJ24/SUM(AF:AF) -> 0.14609819 | AL24: =MIN(AC24,'What-If Analysis'!$B$2) -> 0.19 | AM24: =AE24*(1+'What-If Analysis'!$B$3) -> 40.3 | AN24: =Y24*(1+'What-If Analysis'!$B$4) -> 1277.32 | AO24: =AA24*AM24*(1-AL24) -> 28684.383
A25: ORD-2025-831576 | B25: 45915 | C25: =IF(D25<B25,D25,B25) -> 45915 | D25: 45925 | E25: =IF(D25<B25,B25,D25) -> 45925 | F25: =E25-C25 -> 10 | G25: =IF(Data!F115<=7,1,0) -> 0 | H25: =TEXT(C25,"MM-YYYY") -> 09-2025 | I25: ="Q"&ROUNDUP(MONTH(H25)/3,0)&"-"&YEAR(H25) -> Q3-2025 | J25: =_xlfn.MINIFS(C:C,M:M,M25) -> 44955 | K25: =TEXT(J25,"MM-YYYY") -> 01-2023 | L25: Asia | M25: India | N25: Delhi | O25: =IF(N25="",_xlfn.XLOOKUP(M25,M:M,N:N),N25) -> Delhi | P25: Consumer | Q25: Retail | R25: =IF(Q25="",_xlfn.XLOOKUP(M25,M:M,Q:Q),Q25) -> Retail | S25: A. Patel | T25: =IF(S25="",_xlfn.XLOOKUP(L25,L:L,S:S),S25) -> A. Patel | U25: Phones | V25: =IF(AA25<815.0987,"Low",IF(AA25<1640.058,"Medium","High")) -> Medium | W25: PHN-2859 | X25: =IF(AK25<=80%,"A",IF(AK25<=95%,"B","C")) -> A | Y25: 1488.91 | Z25: 1483.74 | AA25: =ABS(Z25) -> 1483.74 | AB25: 0.168 | AC25: =MIN(AB25,30%) -> 0.168 | AD25: =IF(AC25>20%,1,0) -> 0 | AE25: 24 | AF25: =AA25*AE25*(1-AC25) -> 29627.32 | AG25: =Y25*AE25 -> 35733.84 | AH25: =ABS(AF25-AG25) -> 6106.5197 | AI25: =IF(AF25=0,0,AH25/AF25) -> 0.2061111 | AJ25: =AJ24+AF25 -> 1628784.2 | AK25: =AJ25/SUM(AF:AF) -> 0.14880493 | AL25: =MIN(AC25,'What-If Analysis'!$B$2) -> 0.168 | AM25: =AE25*(1+'What-If Analysis'!$B$3) -> 31.2 | AN25: =Y25*(1+'What-If Analysis'!$B$4) -> 1637.801 | AO25: =AA25*AM25*(1-AL25) -> 38515.516
A26: ORD-2024-468655 | B26: 45341 | C26: =IF(D26<B26,D26,B26) -> 45341 | D26: 45357 | E26: =IF(D26<B26,B26,D26) -> 45357 | F26: =E26-C26 -> 16 | G26: =IF(Data!F23<=7,1,0) -> 0 | H26: =TEXT(C26,"MM-YYYY") -> 02-2024 | I26: ="Q"&ROUNDUP(MONTH(H26)/3,0)&"-"&YEAR(H26) -> Q1-2024 | J26: =_xlfn.MINIFS(C:C,M:M,M26) -> 44938 | K26: =TEXT(J26,"MM-YYYY") -> 01-2023 | L26: Asia | M26: China | N26: Beijing | O26: =IF(N26="",_xlfn.XLOOKUP(M26,M:M,N:N),N26) -> Beijing | P26: Education | Q26: Marketplace | R26: =IF(Q26="",_xlfn.XLOOKUP(M26,M:M,Q:Q),Q26) -> Marketplace | S26: O. Wang | T26: =IF(S26="",_xlfn.XLOOKUP(L26,L:L,S:S),S26) -> O. Wang | U26: Printers | V26: =IF(AA26<815.0987,"Low",IF(AA26<1640.058,"Medium","High")) -> High | W26: PRN-6308 | X26: =IF(AK26<=80%,"A",IF(AK26<=95%,"B","C")) -> A | Y26: 1477.84 | Z26: 3197.47 | AA26: =ABS(Z26) -> 3197.47 | AB26: 0.243 | AC26: =MIN(AB26,30%) -> 0.243 | AD26: =IF(AC26>20%,1,0) -> 1 | AE26: 24 | AF26: =AA26*AE26*(1-AC26) -> 58091.635 | AG26: =Y26*AE26 -> 35468.16 | AH26: =ABS(AF26-AG26) -> 22623.475 | AI26: =IF(AF26=0,0,AH26/AF26) -> 0.38944462 | AJ26: =AJ25+AF26 -> 1686875.8 | AK26: =AJ26/SUM(AF:AF) -> 0.15411215 | AL26: =MIN(AC26,'What-If Analysis'!$B$2) -> 0.2 | AM26: =AE26*(1+'What-If Analysis'!$B$3) -> 31.2 | AN26: =Y26*(1+'What-If Analysis'!$B$4) -> 1625.624 | AO26: =AA26*AM26*(1-AL26) -> 79808.851
A27: ORD-2024-756884 | B27: 45578 | C27: =IF(D27<B27,D27,B27) -> 45578 | D27: 45589 | E27: =IF(D27<B27,B27,D27) -> 45589 | F27: =E27-C27 -> 11 | G27: =IF(Data!F48<=7,1,0) -> 0 | H27: =TEXT(C27,"MM-YYYY") -> 10-2024 | I27: ="Q"&ROUNDUP(MONTH(H27)/3,0)&"-"&YEAR(H27) -> Q4-2024 | J27: =_xlfn.MINIFS(C:C,M:M,M27) -> 44936 | K27: =TEXT(J27,"MM-YYYY") -> 01-2023 | L27: Europe | M27: France | N27: Paris | O27: =IF(N27="",_xlfn.XLOOKUP(M27,M:M,N:N),N27) -> Paris | P27: Education | Q27: Distributor | R27: =IF(Q27="",_xlfn.XLOOKUP(M27,M:M,Q:Q),Q27) -> Distributor | S27: F. Müller | T27: =IF(S27="",_xlfn.XLOOKUP(L27,L:L,S:S),S27) -> F. Müller | U27: Components | V27: =IF(AA27<815.0987,"Low",IF(AA27<1640.058,"Medium","High")) -> Medium | W27: CMP-5006 | X27: =IF(AK27<=80%,"A",IF(AK27<=95%,"B","C")) -> A | Y27: 816.7 | Z27: 1010.75 | AA27: =ABS(Z27) -> 1010.75 | AB27: 0.047 | AC27: =MIN(AB27,30%) -> 0.047 | AD27: =IF(AC27>20%,1,0) -> 0 | AE27: 43 | AF27: =AA27*AE27*(1-AC27) -> 41419.524 | AG27: =Y27*AE27 -> 35118.1 | AH27: =ABS(AF27-AG27) -> 6301.4242 | AI27: =IF(AF27=0,0,AH27/AF27) -> 0.15213657 | AJ27: =AJ26+AF27 -> 1728295.3 | AK27: =AJ27/SUM(AF:AF) -> 0.15789622 | AL27: =MIN(AC27,'What-If Analysis'!$B$2) -> 0.047 | AM27: =AE27*(1+'What-If Analysis'!$B$3) -> 55.9 | AN27: =Y27*(1+'What-If Analysis'!$B$4) -> 898.37 | AO27: =AA27*AM27*(1-AL27) -> 53845.382
A28: ORD-2025-944081 | B28: 45741 | C28: =IF(D28<B28,D28,B28) -> 45741 | D28: 45742 | E28: =IF(D28<B28,B28,D28) -> 45742 | F28: =E28-C28 -> 1 | G28: =IF(Data!F44<=7,1,0) -> 0 | H28: =TEXT(C28,"MM-YYYY") -> 03-2025 | I28: ="Q"&ROUNDUP(MONTH(H28)/3,0)&"-"&YEAR(H28) -> Q1-2025 | J28: =_xlfn.MINIFS(C:C,M:M,M28) -> 44939 | K28: =TEXT(J28,"MM-YYYY") -> 01-2023 | L28: Africa | M28: Nigeria | N28: Lagos | O28: =IF(N28="",_xlfn.XLOOKUP(M28,M:M,N:N),N28) -> Lagos | P28: Education | Q28: Distributor | R28: =IF(Q28="",_xlfn.XLOOKUP(M28,M:M,Q:Q),Q28) -> Distributor | S28: G. Dubois | T28: =IF(S28="",_xlfn.XLOOKUP(L28,L:L,S:S),S28) -> G. Dubois | U28: Accessories | V28: =IF(AA28<815.0987,"Low",IF(AA28<1640.058,"Medium","High")) -> High | W28: ACC-9533 | X28: =IF(AK28<=80%,"A",IF(AK28<=95%,"B","C")) -> A | Y28: 1450.43 | Z28: 1994.67 | AA28: =ABS(Z28) -> 1994.67 | AB28: 0.1 | AC28: =MIN(AB28,30%) -> 0.1 | AD28: =IF(AC28>20%,1,0) -> 0 | AE28: 24 | AF28: =AA28*AE28*(1-AC28) -> 43084.872 | AG28: =Y28*AE28 -> 34810.32 | AH28: =ABS(AF28-AG28) -> 8274.552 | AI28: =IF(AF28=0,0,AH28/AF28) -> 0.19205238 | AJ28: =AJ27+AF28 -> 1771380.2 | AK28: =AJ28/SUM(AF:AF) -> 0.16183243 | AL28: =MIN(AC28,'What-If Analysis'!$B$2) -> 0.1 | AM28: =AE28*(1+'What-If Analysis'!$B$3) -> 31.2 | AN28: =Y28*(1+'What-If Analysis'!$B$4) -> 1595.473 | AO28: =AA28*AM28*(1-AL28) -> 56010.334
A29: ORD-2024-341535 | B29: 45468 | C29: =IF(D29<B29,D29,B29) -> 45468 | D29: 45473 | E29: =IF(D29<B29,B29,D29) -> 45473 | F29: =E29-C29 -> 5 | G29: =IF(Data!F10<=7,1,0) -> 0 | H29: =TEXT(C29,"MM-YYYY") -> 06-2024 | I29: ="Q"&ROUNDUP(MONTH(H29)/3,0)&"-"&YEAR(H29) -> Q2-2024 | J29: =_xlfn.MINIFS(C:C,M:M,M29) -> 44946 | K29: =TEXT(J29,"MM-YYYY") -> 01-2023 | L29: Africa | M29: Kenya | N29: Kisumu | O29: =IF(N29="",_xlfn.XLOOKUP(M29,M:M,N:N),N29) -> Kisumu | P29: Education | Q29: Direct | R29: =IF(Q29="",_xlfn.XLOOKUP(M29,M:M,Q:Q),Q29) -> Direct | S29: M. Rossi | T29: =IF(S29="",_xlfn.XLOOKUP(L29,L:L,S:S),S29) -> M. Rossi | U29: Networking | V29: =IF(AA29<815.0987,"Low",IF(AA29<1640.058,"Medium","High")) -> High | W29: NET-5987 | X29: =IF(AK29<=80%,"A",IF(AK29<=95%,"B","C")) -> A | Y29: 1323.55 | Z29: 3230.35 | AA29: =ABS(Z29) -> 3230.35 | AB29: 0.022 | AC29: =MIN(AB29,30%) -> 0.022 | AD29: =IF(AC29>20%,1,0) -> 0 | AE29: 26 | AF29: =AA29*AE29*(1-AC29) -> 82141.34 | AG29: =Y29*AE29 -> 34412.3 | AH29: =ABS(AF29-AG29) -> 47729.04 | AI29: =IF(AF29=0,0,AH29/AF29) -> 0.58105991 | AJ29: =AJ28+AF29 -> 1853521.5 | AK29: =AJ29/SUM(AF:AF) -> 0.16933682 | AL29: =MIN(AC29,'What-If Analysis'!$B$2) -> 0.022 | AM29: =AE29*(1+'What-If Analysis'!$B$3) -> 33.8 | AN29: =Y29*(1+'What-If Analysis'!$B$4) -> 1455.905 | AO29: =AA29*AM29*(1-AL29) -> 106783.74
A30: ORD-2024-572312 | B30: 45459 | C30: =IF(D30<B30,D30,B30) -> 45459 | D30: 45464 | E30: =IF(D30<B30,B30,D30) -> 45464 | F30: =E30-C30 -> 5 | G30: =IF(Data!F14<=7,1,0) -> 1 | H30: =TEXT(C30,"MM-YYYY") -> 06-2024 | I30: ="Q"&ROUNDUP(MONTH(H30)/3,0)&"-"&YEAR(H30) -> Q2-2024 | J30: =_xlfn.MINIFS(C:C,M:M,M30) -> 44988 | K30: =TEXT(J30,"MM-YYYY") -> 03-2023 | L30: Asia | M30: Japan | N30: Tokyo | O30: =IF(N30="",_xlfn.XLOOKUP(M30,M:M,N:N),N30) -> Tokyo | P30: Small Business | Q30: Distributor | R30: =IF(Q30="",_xlfn.XLOOKUP(M30,M:M,Q:Q),Q30) -> Distributor | S30: F. Müller | T30: =IF(S30="",_xlfn.XLOOKUP(L30,L:L,S:S),S30) -> F. Müller | U30: Phones | V30: =IF(AA30<815.0987,"Low",IF(AA30<1640.058,"Medium","High")) -> High | W30: PHN-9677 | X30: =IF(AK30<=80%,"A",IF(AK30<=95%,"B","C")) -> A | Y30: 1367.13 | Z30: 3062.01 | AA30: =ABS(Z30) -> 3062.01 | AB30: 0.103 | AC30: =MIN(AB30,30%) -> 0.103 | AD30: =IF(AC30>20%,1,0) -> 0 | AE30: 25 | AF30: =AA30*AE30*(1-AC30) -> 68665.574 | AG30: =Y30*AE30 -> 34178.25 | AH30: =ABS(AF30-AG30) -> 34487.324 | AI30: =IF(AF30=0,0,AH30/AF30) -> 0.50225058 | AJ30: =AJ29+AF30 -> 1922187.1 | AK30: =AJ30/SUM(AF:AF) -> 0.17561007 | AL30: =MIN(AC30,'What-If Analysis'!$B$2) -> 0.103 | AM30: =AE30*(1+'What-If Analysis'!$B$3) -> 32.5 | AN30: =Y30*(1+'What-If Analysis'!$B$4) -> 1503.843 | AO30: =AA30*AM30*(1-AL30) -> 89265.247
A31: ORD-2024-868223 | B31: 45354 | C31: =IF(D31<B31,D31,B31) -> 45354 | D31: 45370 | E31: =IF(D31<B31,B31,D31) -> 45370 | F31: =E31-C31 -> 16 | G31: =IF(Data!F64<=7,1,0) -> 0 | H31: =TEXT(C31,"MM-YYYY") -> 03-2024 | I31: ="Q"&ROUNDUP(MONTH(H31)/3,0)&"-"&YEAR(H31) -> Q1-2024 | J31: =_xlfn.MINIFS(C:C,M:M,M31) -> 44938 | K31: =TEXT(J31,"MM-YYYY") -> 01-2023 | L31: Asia | M31: China | N31: Beijing | O31: =IF(N31="",_xlfn.XLOOKUP(M31,M:M,N:N),N31) -> Beijing | P31: Consumer | Q31: Distributor | R31: =IF(Q31="",_xlfn.XLOOKUP(M31,M:M,Q:Q),Q31) -> Distributor | S31: G. Dubois | T31: =IF(S31="",_xlfn.XLOOKUP(L31,L:L,S:S),S31) -> G. Dubois | U31: Phones | V31: =IF(AA31<815.0987,"Low",IF(AA31<1640.058,"Medium","High")) -> Medium | W31: PHN-4915 | X31: =IF(AK31<=80%,"A",IF(AK31<=95%,"B","C")) -> A | Y31: 988.83 | Z31: 1206.04 | AA31: =ABS(Z31) -> 1206.04 | AB31: 0.063 | AC31: =MIN(AB31,30%) -> 0.063 | AD31: =IF(AC31>20%,1,0) -> 0 | AE31: 34 | AF31: =AA31*AE31*(1-AC31) -> 38422.022 | AG31: =Y31*AE31 -> 33620.22 | AH31: =ABS(AF31-AG31) -> 4801.8023 | AI31: =IF(AF31=0,0,AH31/AF31) -> 0.12497526 | AJ31: =AJ30+AF31 -> 1960609.1 | AK31: =AJ31/SUM(AF:AF) -> 0.17912029 | AL31: =MIN(AC31,'What-If Analysis'!$B$2) -> 0.063 | AM31: =AE31*(1+'What-If Analysis'!$B$3) -> 44.2 | AN31: =Y31*(1+'What-If Analysis'!$B$4) -> 1087.713 | AO31: =AA31*AM31*(1-AL31) -> 49948.629
A32: ORD-2024-358795 | B32: 45588 | C32: =IF(D32<B32,D32,B32) -> 45587 | D32: 45587 | E32: =IF(D32<B32,B32,D32) -> 45588 | F32: =E32-C32 -> 1 | G32: =IF(Data!F223<=7,1,0) -> 0 | H32: =TEXT(C32,"MM-YYYY") -> 10-2024 | I32: ="Q"&ROUNDUP(MONTH(H32)/3,0)&"-"&YEAR(H32) -> Q4-2024 | J32: =_xlfn.MINIFS(C:C,M:M,M32) -> 44939 | K32: =TEXT(J32,"MM-YYYY") -> 01-2023 | L32: Africa | M32: Nigeria | N32: Port Harcourt | O32: =IF(N32="",_xlfn.XLOOKUP(M32,M:M,N:N),N32) -> Port Harcourt | P32: Education | Q32: Online | R32: =IF(Q32="",_xlfn.XLOOKUP(M32,M:M,Q:Q),Q32) -> Online | S32: J. Njeri | T32: =IF(S32="",_xlfn.XLOOKUP(L32,L:L,S:S),S32) -> J. Njeri | U32: Printers | V32: =IF(AA32<815.0987,"Low",IF(AA32<1640.058,"Medium","High")) -> Low | W32: PRN-9322 | X32: =IF(AK32<=80%,"A",IF(AK32<=95%,"B","C")) -> A | Y32: 1084.39 | Z32: 759.33 | AA32: =ABS(Z32) -> 759.33 | AB32: 0.237 | AC32: =MIN(AB32,30%) -> 0.237 | AD32: =IF(AC32>20%,1,0) -> 1 | AE32: 31 | AF32: =AA32*AE32*(1-AC32) -> 17960.432 | AG32: =Y32*AE32 -> 33616.09 | AH32: =ABS(AF32-AG32) -> 15655.658 | AI32: =IF(AF32=0,0,AH32/AF32) -> 0.87167486 | AJ32: =AJ31+AF32 -> 1978569.6 | AK32: =AJ32/SUM(AF:AF) -> 0.18076115 | AL32: =MIN(AC32,'What-If Analysis'!$B$2) -> 0.2 | AM32: =AE32*(1+'What-If Analysis'!$B$3) -> 40.3 | AN32: =Y32*(1+'What-If Analysis'!$B$4) -> 1192.829 | AO32: =AA32*AM32*(1-AL32) -> 24480.799
A33: ORD-2025-440093 | B33: 45763 | C33: =IF(D33<B33,D33,B33) -> 45763 | D33: 45773 | E33: =IF(D33<B33,B33,D33) -> 45773 | F33: =E33-C33 -> 10 | G33: =IF(Data!F56<=7,1,0) -> 1 | H33: =TEXT(C33,"MM-YYYY") -> 04-2025 | I33: ="Q"&ROUNDUP(MONTH(H33)/3,0)&"-"&YEAR(H33) -> Q2-2025 | J33: =_xlfn.MINIFS(C:C,M:M,M33) -> 44939 | K33: =TEXT(J33,"MM-YYYY") -> 01-2023 | L33: Africa | M33: Nigeria | N33: Port Harcourt | O33: =IF(N33="",_xlfn.XLOOKUP(M33,M:M,N:N),N33) -> Port Harcourt | P33: Enterprise | Q33: Marketplace | R33: =IF(Q33="",_xlfn.XLOOKUP(M33,M:M,Q:Q),Q33) -> Marketplace | S33: F. Müller | T33: =IF(S33="",_xlfn.XLOOKUP(L33,L:L,S:S),S33) -> F. Müller | U33: Laptops | V33: =IF(AA33<815.0987,"Low",IF(AA33<1640.058,"Medium","High")) -> High | W33: LAP-3490 | X33: =IF(AK33<=80%,"A",IF(AK33<=95%,"B","C")) -> A | Y33: 1457.44 | Z33: 1996.81 | AA33: =ABS(Z33) -> 1996.81 | AB33: 0.126 | AC33: =MIN(AB33,30%) -> 0.126 | AD33: =IF(AC33>20%,1,0) -> 0 | AE33: 23 | AF33: =AA33*AE33*(1-AC33) -> 40139.875 | AG33: =Y33*AE33 -> 33521.12 | AH33: =ABS(AF33-AG33) -> 6618.7546 | AI33: =IF(AF33=0,0,AH33/AF33) -> 0.16489226 | AJ33: =AJ32+AF33 -> 2018709.4 | AK33: =AJ33/SUM(AF:AF) -> 0.18442831 | AL33: =MIN(AC33,'What-If Analysis'!$B$2) -> 0.126 | AM33: =AE33*(1+'What-If Analysis'!$B$3) -> 29.9 | AN33: =Y33*(1+'What-If Analysis'!$B$4) -> 1603.184 | AO33: =AA33*AM33*(1-AL33) -> 52181.837
A34: ORD-2023-701153 | B34: 45030 | C34: =IF(D34<B34,D34,B34) -> 45030 | D34: 45059 | E34: =IF(D34<B34,B34,D34) -> 45059 | F34: =E34-C34 -> 29 | G34: =IF(Data!F26<=7,1,0) -> 0 | H34: =TEXT(C34,"MM-YYYY") -> 04-2023 | I34: ="Q"&ROUNDUP(MONTH(H34)/3,0)&"-"&YEAR(H34) -> Q2-2023 | J34: =_xlfn.MINIFS(C:C,M:M,M34) -> 44947 | K34: =TEXT(J34,"MM-YYYY") -> 01-2023 | L34: Europe | M34: Germany | N34: Frankfurt | O34: =IF(N34="",_xlfn.XLOOKUP(M34,M:M,N:N),N34) -> Frankfurt | P34: Consumer | Q34: Direct | R34: =IF(Q34="",_xlfn.XLOOKUP(M34,M:M,Q:Q),Q34) -> Direct | S34: J. Njeri | T34: =IF(S34="",_xlfn.XLOOKUP(L34,L:L,S:S),S34) -> J. Njeri | U34: Printers | V34: =IF(AA34<815.0987,"Low",IF(AA34<1640.058,"Medium","High")) -> High | W34: PRN-7019 | X34: =IF(AK34<=80%,"A",IF(AK34<=95%,"B","C")) -> A | Y34: 1320.33 | Z34: 2645.23 | AA34: =ABS(Z34) -> 2645.23 | AB34: 0.155 | AC34: =MIN(AB34,30%) -> 0.155 | AD34: =IF(AC34>20%,1,0) -> 0 | AE34: 25 | AF34: =AA34*AE34*(1-AC34) -> 55880.484 | AG34: =Y34*AE34 -> 33008.25 | AH34: =ABS(AF34-AG34) -> 22872.234 | AI34: =IF(AF34=0,0,AH34/AF34) -> 0.40930629 | AJ34: =AJ33+AF34 -> 2074589.9 | AK34: =AJ34/SUM(AF:AF) -> 0.18953352 | AL34: =MIN(AC34,'What-If Analysis'!$B$2) -> 0.155 | AM34: =AE34*(1+'What-If Analysis'!$B$3) -> 32.5 | AN34: =Y34*(1+'What-If Analysis'!$B$4) -> 1452.363 | AO34: =AA34*AM34*(1-AL34) -> 72644.629
A35: ORD-2025-765220 | B35: 45753 | C35: =IF(D35<B35,D35,B35) -> 45753 | D35: 45777 | E35: =IF(D35<B35,B35,D35) -> 45777 | F35: =E35-C35 -> 24 | G35: =IF(Data!F98<=7,1,0) -> 0 | H35: =TEXT(C35,"MM-YYYY") -> 04-2025 | I35: ="Q"&ROUNDUP(MONTH(H35)/3,0)&"-"&YEAR(H35) -> Q2-2025 | J35: =_xlfn.MINIFS(C:C,M:M,M35) -> 44955 | K35: =TEXT(J35,"MM-YYYY") -> 01-2023 | L35: Americas | M35: Brazil | N35: Brasília | O35: =IF(N35="",_xlfn.XLOOKUP(M35,M:M,N:N),N35) -> Brasília | P35: Education | Q35: Online | R35: =IF(Q35="",_xlfn.XLOOKUP(M35,M:M,Q:Q),Q35) -> Online | S35: K. Singh | T35: =IF(S35="",_xlfn.XLOOKUP(L35,L:L,S:S),S35) -> K. Singh | U35: Monitors | V35: =IF(AA35<815.0987,"Low",IF(AA35<1640.058,"Medium","High")) -> Medium | W35: MON-4925 | X35: =IF(AK35<=80%,"A",IF(AK35<=95%,"B","C")) -> A | Y35: 855.78 | Z35: 977.38 | AA35: =ABS(Z35) -> 977.38 | AB35: 0.147 | AC35: =MIN(AB35,30%) -> 0.147 | AD35: =IF(AC35>20%,1,0) -> 0 | AE35: 38 | AF35: =AA35*AE35*(1-AC35) -> 31680.795 | AG35: =Y35*AE35 -> 32519.64 | AH35: =ABS(AF35-AG35) -> 838.84468 | AI35: =IF(AF35=0,0,AH35/AF35) -> 0.026478018 | AJ35: =AJ34+AF35 -> 2106270.7 | AK35: =AJ35/SUM(AF:AF) -> 0.19242786 | AL35: =MIN(AC35,'What-If Analysis'!$B$2) -> 0.147 | AM35: =AE35*(1+'What-If Analysis'!$B$3) -> 49.4 | AN35: =Y35*(1+'What-If Analysis'!$B$4) -> 941.358 | AO35: =AA35*AM35*(1-AL35) -> 41185.034
A36: ORD-2024-817997 | B36: 45501 | C36: =IF(D36<B36,D36,B36) -> 45501 | D36: 45527 | E36: =IF(D36<B36,B36,D36) -> 45527 | F36: =E36-C36 -> 26 | G36: =IF(Data!F110<=7,1,0) -> 0 | H36: =TEXT(C36,"MM-YYYY") -> 07-2024 | I36: ="Q"&ROUNDUP(MONTH(H36)/3,0)&"-"&YEAR(H36) -> Q3-2024 | J36: =_xlfn.MINIFS(C:C,M:M,M36) -> 44955 | K36: =TEXT(J36,"MM-YYYY") -> 01-2023 | L36: Asia | M36: India | N36: Hyderabad | O36: =IF(N36="",_xlfn.XLOOKUP(M36,M:M,N:N),N36) -> Hyderabad | P36: Corporate | Q36: Retail | R36: =IF(Q36="",_xlfn.XLOOKUP(M36,M:M,Q:Q),Q36) -> Retail | S36: J. Njeri | T36: =IF(S36="",_xlfn.XLOOKUP(L36,L:L,S:S),S36) -> J. Njeri | U36: Networking | V36: =IF(AA36<815.0987,"Low",IF(AA36<1640.058,"Medium","High")) -> Medium | W36: NET-4675 | X36: =IF(AK36<=80%,"A",IF(AK36<=95%,"B","C")) -> A | Y36: 1339.24 | Z36: 1558.89 | AA36: =ABS(Z36) -> 1558.89 | AB36: 0.192 | AC36: =MIN(AB36,30%) -> 0.192 | AD36: =IF(AC36>20%,1,0) -> 0 | AE36: 24 | AF36: =AA36*AE36*(1-AC36) -> 30229.995 | AG36: =Y36*AE36 -> 32141.76 | AH36: =ABS(AF36-AG36) -> 1911.7651 | AI36: =IF(AF36=0,0,AH36/AF36) -> 0.06324067 | AJ36: =AJ35+AF36 -> 2136500.7 | AK36: =AJ36/SUM(AF:AF) -> 0.19518966 | AL36: =MIN(AC36,'What-If Analysis'!$B$2) -> 0.192 | AM36: =AE36*(1+'What-If Analysis'!$B$3) -> 31.2 | AN36: =Y36*(1+'What-If Analysis'!$B$4) -> 1473.164 | AO36: =AA36*AM36*(1-AL36) -> 39298.993
A37: ORD-2024-805860 | B37: 45548 | C37: =IF(D37<B37,D37,B37) -> 45548 | D37: 45567 | E37: =IF(D37<B37,B37,D37) -> 45567 | F37: =E37-C37 -> 19 | G37: =IF(Data!F67<=7,1,0) -> 0 | H37: =TEXT(C37,"MM-YYYY") -> 09-2024 | I37: ="Q"&ROUNDUP(MONTH(H37)/3,0)&"-"&YEAR(H37) -> Q3-2024 | J37: =_xlfn.MINIFS(C:C,M:M,M37) -> 44946 | K37: =TEXT(J37,"MM-YYYY") -> 01-2023 | L37: Africa | M37: Kenya | N37: Mombasa | O37: =IF(N37="",_xlfn.XLOOKUP(M37,M:M,N:N),N37) -> Mombasa | P37: Small Business | Q37: Retail | R37: =IF(Q37="",_xlfn.XLOOKUP(M37,M:M,Q:Q),Q37) -> Retail | S37: M. Rossi | T37: =IF(S37="",_xlfn.XLOOKUP(L37,L:L,S:S),S37) -> M. Rossi | U37: Phones | V37: =IF(AA37<815.0987,"Low",IF(AA37<1640.058,"Medium","High")) -> High | W37: PHN-8804 | X37: =IF(AK37<=80%,"A",IF(AK37<=95%,"B","C")) -> A | Y37: 1338.99 | Z37: 1765.76 | AA37: =ABS(Z37) -> 1765.76 | AB37: 0.126 | AC37: =MIN(AB37,30%) -> 0.126 | AD37: =IF(AC37>20%,1,0) -> 0 | AE37: 24 | AF37: =AA37*AE37*(1-AC37) -> 37038.582 | AG37: =Y37*AE37 -> 32135.76 | AH37: =ABS(AF37-AG37) -> 4902.8218 | AI37: =IF(AF37=0,0,AH37/AF37) -> 0.13237067 | AJ37: =AJ36+AF37 -> 2173539.3 | AK37: =AJ37/SUM(AF:AF) -> 0.19857349 | AL37: =MIN(AC37,'What-If Analysis'!$B$2) -> 0.126 | AM37: =AE37*(1+'What-If Analysis'!$B$3) -> 31.2 | AN37: =Y37*(1+'What-If Analysis'!$B$4) -> 1472.889 | AO37: =AA37*AM37*(1-AL37) -> 48150.156
